2025-06-12 03:31:39,087 - generators.youtube.downloader - INFO - üç™ Utilisation des cookies YouTube : D:\betisespython\blocs\youtubeauto\cookies\cookies_yt.txt
2025-06-12 03:31:39,087 - generators.youtube.downloader - INFO - üì• T√©l√©chargement depuis : https://www.youtube.com/watch?v=dQw4w9WgXcQ
2025-06-12 03:31:41,333 - generators.youtube.downloader - ERROR - ‚ùå √âchec du t√©l√©chargement
Traceback (most recent call last):
  File "C:\Users\biott\AppData\Local\Programs\Python\Python310\lib\site-packages\yt_dlp\YoutubeDL.py", line 1662, in wrapper
    return func(self, *args, **kwargs)
  File "C:\Users\biott\AppData\Local\Programs\Python\Python310\lib\site-packages\yt_dlp\YoutubeDL.py", line 1818, in __extract_info
    return self.process_ie_result(ie_result, download, extra_info)
  File "C:\Users\biott\AppData\Local\Programs\Python\Python310\lib\site-packages\yt_dlp\YoutubeDL.py", line 1877, in process_ie_result
    ie_result = self.process_video_result(ie_result, download=download)
  File "C:\Users\biott\AppData\Local\Programs\Python\Python310\lib\site-packages\yt_dlp\YoutubeDL.py", line 3011, in process_video_result
    raise ExtractorError(
yt_dlp.utils.ExtractorError: [youtube] dQw4w9WgXcQ: Requested format is not available. Use --list-formats for a list of available formats

During handling of the above exception, another exception occurred:

Traceback (most recent call last):
  File "D:\betisespython\blocs\youtubeauto\generators\youtube\downloader.py", line 32, in download
    info = ydl.extract_info(youtube_url, download=True)
  File "C:\Users\biott\AppData\Local\Programs\Python\Python310\lib\site-packages\yt_dlp\YoutubeDL.py", line 1651, in extract_info
    return self.__extract_info(url, self.get_info_extractor(key), download, extra_info, process)
  File "C:\Users\biott\AppData\Local\Programs\Python\Python310\lib\site-packages\yt_dlp\YoutubeDL.py", line 1680, in wrapper
    self.report_error(str(e), e.format_traceback())
  File "C:\Users\biott\AppData\Local\Programs\Python\Python310\lib\site-packages\yt_dlp\YoutubeDL.py", line 1120, in report_error
    self.trouble(f'{self._format_err("ERROR:", self.Styles.ERROR)} {message}', *args, **kwargs)
  File "C:\Users\biott\AppData\Local\Programs\Python\Python310\lib\site-packages\yt_dlp\YoutubeDL.py", line 1059, in trouble
    raise DownloadError(message, exc_info)
yt_dlp.utils.DownloadError: [0;31mERROR:[0m [youtube] dQw4w9WgXcQ: Requested format is not available. Use --list-formats for a list of available formats
