2025-06-12 03:30:54,206 - prompts - INFO - üì• Prompts personnalis√©s charg√©s depuis custom_prompts.json
2025-06-12 03:30:54,220 - __main__ - INFO - üöÄ Traitement de la vid√©o : https://www.youtube.com/watch?v=N8KLrTIz8aE (slug: yt_test)
2025-06-12 03:30:56,175 - __main__ - ERROR - ‚ùå Pipeline √©chou√©.
Traceback (most recent call last):
  File "C:\Users\biott\AppData\Local\Programs\Python\Python310\lib\site-packages\yt_dlp\YoutubeDL.py", line 1662, in wrapper
    return func(self, *args, **kwargs)
  File "C:\Users\biott\AppData\Local\Programs\Python\Python310\lib\site-packages\yt_dlp\YoutubeDL.py", line 1818, in __extract_info
    return self.process_ie_result(ie_result, download, extra_info)
  File "C:\Users\biott\AppData\Local\Programs\Python\Python310\lib\site-packages\yt_dlp\YoutubeDL.py", line 1877, in process_ie_result
    ie_result = self.process_video_result(ie_result, download=download)
  File "C:\Users\biott\AppData\Local\Programs\Python\Python310\lib\site-packages\yt_dlp\YoutubeDL.py", line 3011, in process_video_result
    raise ExtractorError(
yt_dlp.utils.ExtractorError: [youtube] N8KLrTIz8aE: Requested format is not available. Use --list-formats for a list of available formats

During handling of the above exception, another exception occurred:

Traceback (most recent call last):
  File "D:\betisespython\blocs\youtubeauto\main.py", line 24, in main
    video_path = downloader.download(youtube_url, slug)
  File "D:\betisespython\blocs\youtubeauto\generators\youtube\downloader.py", line 32, in download
    info = ydl.extract_info(youtube_url, download=True)
  File "C:\Users\biott\AppData\Local\Programs\Python\Python310\lib\site-packages\yt_dlp\YoutubeDL.py", line 1651, in extract_info
    return self.__extract_info(url, self.get_info_extractor(key), download, extra_info, process)
  File "C:\Users\biott\AppData\Local\Programs\Python\Python310\lib\site-packages\yt_dlp\YoutubeDL.py", line 1680, in wrapper
    self.report_error(str(e), e.format_traceback())
  File "C:\Users\biott\AppData\Local\Programs\Python\Python310\lib\site-packages\yt_dlp\YoutubeDL.py", line 1120, in report_error
    self.trouble(f'{self._format_err("ERROR:", self.Styles.ERROR)} {message}', *args, **kwargs)
  File "C:\Users\biott\AppData\Local\Programs\Python\Python310\lib\site-packages\yt_dlp\YoutubeDL.py", line 1059, in trouble
    raise DownloadError(message, exc_info)
yt_dlp.utils.DownloadError: [0;31mERROR:[0m [youtube] N8KLrTIz8aE: Requested format is not available. Use --list-formats for a list of available formats
